Traceback (most recent call last):
  File "/Users/Yannick/opt/anaconda3/envs/ex/lib/python3.8/site-packages/jupyter_cache/executors/utils.py", line 58, in single_nb_execution
    executenb(
  File "/Users/Yannick/opt/anaconda3/envs/ex/lib/python3.8/site-packages/nbclient/client.py", line 1204, in execute
    return NotebookClient(nb=nb, resources=resources, km=km, **kwargs).execute()
  File "/Users/Yannick/opt/anaconda3/envs/ex/lib/python3.8/site-packages/nbclient/util.py", line 84, in wrapped
    return just_run(coro(*args, **kwargs))
  File "/Users/Yannick/opt/anaconda3/envs/ex/lib/python3.8/site-packages/nbclient/util.py", line 62, in just_run
    return loop.run_until_complete(coro)
  File "/Users/Yannick/opt/anaconda3/envs/ex/lib/python3.8/asyncio/base_events.py", line 616, in run_until_complete
    return future.result()
  File "/Users/Yannick/opt/anaconda3/envs/ex/lib/python3.8/site-packages/nbclient/client.py", line 663, in async_execute
    await self.async_execute_cell(
  File "/Users/Yannick/opt/anaconda3/envs/ex/lib/python3.8/site-packages/nbclient/client.py", line 965, in async_execute_cell
    await self._check_raise_for_error(cell, cell_index, exec_reply)
  File "/Users/Yannick/opt/anaconda3/envs/ex/lib/python3.8/site-packages/nbclient/client.py", line 862, in _check_raise_for_error
    raise CellExecutionError.from_cell_and_msg(cell, exec_reply_content)
nbclient.exceptions.CellExecutionError: An error occurred while executing the following cell:
------------------
months = {"Januar": 31, "Februar": 28, "MÃ¤rz": 31, "April": 30, "Mai": 31, "Juni": 30, "Juli": 31, "August": 31, "September": 30, "Oktober": 31, "November": 30, "Dezember": 31}
weekdays = ["Montag", "Dienstag", "Mittwoch", "Donnerstag", "Freitag", "Samstag", "Sonntag"]


j = 5
for month, days in months.items():
    for i in range(days):
        print(weekdays[j], ", ", i+1, ". ", month, sep="")
        j += 1
        if j == 7:
            j = 0

print(count)
------------------

[0;31m---------------------------------------------------------------------------[0m
[0;31mNameError[0m                                 Traceback (most recent call last)
[0;32m/var/folders/dy/1d_wflpx5_57vhd_6cdbfk0m0000gn/T/ipykernel_40138/3684105398.py[0m in [0;36m<module>[0;34m[0m
[1;32m     11[0m             [0mj[0m [0;34m=[0m [0;36m0[0m[0;34m[0m[0;34m[0m[0m
[1;32m     12[0m [0;34m[0m[0m
[0;32m---> 13[0;31m [0mprint[0m[0;34m([0m[0mcount[0m[0;34m)[0m[0;34m[0m[0;34m[0m[0m
[0m
[0;31mNameError[0m: name 'count' is not defined
NameError: name 'count' is not defined

