Traceback (most recent call last):
  File "/Users/Yannick/opt/anaconda3/envs/ex/lib/python3.8/site-packages/jupyter_cache/executors/utils.py", line 58, in single_nb_execution
    executenb(
  File "/Users/Yannick/opt/anaconda3/envs/ex/lib/python3.8/site-packages/nbclient/client.py", line 1204, in execute
    return NotebookClient(nb=nb, resources=resources, km=km, **kwargs).execute()
  File "/Users/Yannick/opt/anaconda3/envs/ex/lib/python3.8/site-packages/nbclient/util.py", line 84, in wrapped
    return just_run(coro(*args, **kwargs))
  File "/Users/Yannick/opt/anaconda3/envs/ex/lib/python3.8/site-packages/nbclient/util.py", line 62, in just_run
    return loop.run_until_complete(coro)
  File "/Users/Yannick/opt/anaconda3/envs/ex/lib/python3.8/asyncio/base_events.py", line 616, in run_until_complete
    return future.result()
  File "/Users/Yannick/opt/anaconda3/envs/ex/lib/python3.8/site-packages/nbclient/client.py", line 663, in async_execute
    await self.async_execute_cell(
  File "/Users/Yannick/opt/anaconda3/envs/ex/lib/python3.8/site-packages/nbclient/client.py", line 965, in async_execute_cell
    await self._check_raise_for_error(cell, cell_index, exec_reply)
  File "/Users/Yannick/opt/anaconda3/envs/ex/lib/python3.8/site-packages/nbclient/client.py", line 862, in _check_raise_for_error
    raise CellExecutionError.from_cell_and_msg(cell, exec_reply_content)
nbclient.exceptions.CellExecutionError: An error occurred while executing the following cell:
------------------
#Achtung: anderer Pfad als im Notebook, da das LÃ¶sungsnotebook in einem anderen Verzeichnis liegt 
#Code funktioniert erst, nachdem Du das Dokument "quelltext.txt" erstellt hast!
with open("../../3_Dateien/Fussball/quelltext.txt") as f:
    source_code = f.read()
    
regex = r"/spielbericht/[\w-]+/" #literal "/spielbericht/", ein oder mehrere alphanumerische Zeichen bzw. literal "-", literal "/"

matches = re.findall(regex, source_code)

links = []
for match in matches:
    links.append("www.weltfussball.de" + match)
print(links)
------------------

[0;31m---------------------------------------------------------------------------[0m
[0;31mFileNotFoundError[0m                         Traceback (most recent call last)
[0;32m/var/folders/dy/1d_wflpx5_57vhd_6cdbfk0m0000gn/T/ipykernel_40178/3161933303.py[0m in [0;36m<module>[0;34m[0m
[1;32m      1[0m [0;31m#Achtung: anderer Pfad als im Notebook, da das LÃ¶sungsnotebook in einem anderen Verzeichnis liegt[0m[0;34m[0m[0;34m[0m[0m
[1;32m      2[0m [0;31m#Code funktioniert erst, nachdem Du das Dokument "quelltext.txt" erstellt hast![0m[0;34m[0m[0;34m[0m[0m
[0;32m----> 3[0;31m [0;32mwith[0m [0mopen[0m[0;34m([0m[0;34m"../../3_Dateien/Fussball/quelltext.txt"[0m[0;34m)[0m [0;32mas[0m [0mf[0m[0;34m:[0m[0;34m[0m[0;34m[0m[0m
[0m[1;32m      4[0m     [0msource_code[0m [0;34m=[0m [0mf[0m[0;34m.[0m[0mread[0m[0;34m([0m[0;34m)[0m[0;34m[0m[0;34m[0m[0m
[1;32m      5[0m [0;34m[0m[0m

[0;31mFileNotFoundError[0m: [Errno 2] No such file or directory: '../../3_Dateien/Fussball/quelltext.txt'
FileNotFoundError: [Errno 2] No such file or directory: '../../3_Dateien/Fussball/quelltext.txt'

