Traceback (most recent call last):
  File "/Users/Yannick/opt/anaconda3/envs/ex/lib/python3.8/site-packages/jupyter_cache/executors/utils.py", line 58, in single_nb_execution
    executenb(
  File "/Users/Yannick/opt/anaconda3/envs/ex/lib/python3.8/site-packages/nbclient/client.py", line 1204, in execute
    return NotebookClient(nb=nb, resources=resources, km=km, **kwargs).execute()
  File "/Users/Yannick/opt/anaconda3/envs/ex/lib/python3.8/site-packages/nbclient/util.py", line 84, in wrapped
    return just_run(coro(*args, **kwargs))
  File "/Users/Yannick/opt/anaconda3/envs/ex/lib/python3.8/site-packages/nbclient/util.py", line 62, in just_run
    return loop.run_until_complete(coro)
  File "/Users/Yannick/opt/anaconda3/envs/ex/lib/python3.8/asyncio/base_events.py", line 616, in run_until_complete
    return future.result()
  File "/Users/Yannick/opt/anaconda3/envs/ex/lib/python3.8/site-packages/nbclient/client.py", line 663, in async_execute
    await self.async_execute_cell(
  File "/Users/Yannick/opt/anaconda3/envs/ex/lib/python3.8/site-packages/nbclient/client.py", line 965, in async_execute_cell
    await self._check_raise_for_error(cell, cell_index, exec_reply)
  File "/Users/Yannick/opt/anaconda3/envs/ex/lib/python3.8/site-packages/nbclient/client.py", line 862, in _check_raise_for_error
    raise CellExecutionError.from_cell_and_msg(cell, exec_reply_content)
nbclient.exceptions.CellExecutionError: An error occurred while executing the following cell:
------------------
from matplotlib import rcParams, cycler
import matplotlib.pyplot as plt
import numpy as np
plt.ion()
------------------

[0;31m---------------------------------------------------------------------------[0m
[0;31mImportError[0m                               Traceback (most recent call last)
[0;32m/var/folders/dy/1d_wflpx5_57vhd_6cdbfk0m0000gn/T/ipykernel_37141/2191868119.py[0m in [0;36m<module>[0;34m[0m
[0;32m----> 1[0;31m [0;32mfrom[0m [0mmatplotlib[0m [0;32mimport[0m [0mrcParams[0m[0;34m,[0m [0mcycler[0m[0;34m[0m[0;34m[0m[0m
[0m[1;32m      2[0m [0;32mimport[0m [0mmatplotlib[0m[0;34m.[0m[0mpyplot[0m [0;32mas[0m [0mplt[0m[0;34m[0m[0;34m[0m[0m
[1;32m      3[0m [0;32mimport[0m [0mnumpy[0m [0;32mas[0m [0mnp[0m[0;34m[0m[0;34m[0m[0m
[1;32m      4[0m [0mplt[0m[0;34m.[0m[0mion[0m[0;34m([0m[0;34m)[0m[0;34m[0m[0;34m[0m[0m

[0;32m/Library/Frameworks/Python.framework/Versions/3.10/lib/python3.10/site-packages/matplotlib/__init__.py[0m in [0;36m<module>[0;34m[0m
[1;32m    107[0m [0;31m# cbook must import matplotlib only within function[0m[0;34m[0m[0;34m[0m[0m
[1;32m    108[0m [0;31m# definitions, so it is safe to import from it here.[0m[0;34m[0m[0;34m[0m[0m
[0;32m--> 109[0;31m [0;32mfrom[0m [0;34m.[0m [0;32mimport[0m [0m_api[0m[0;34m,[0m [0m_version[0m[0;34m,[0m [0mcbook[0m[0;34m,[0m [0mdocstring[0m[0;34m,[0m [0mrcsetup[0m[0;34m[0m[0;34m[0m[0m
[0m[1;32m    110[0m [0;32mfrom[0m [0mmatplotlib[0m[0;34m.[0m[0mcbook[0m [0;32mimport[0m [0mMatplotlibDeprecationWarning[0m[0;34m,[0m [0msanitize_sequence[0m[0;34m[0m[0;34m[0m[0m
[1;32m    111[0m [0;32mfrom[0m [0mmatplotlib[0m[0;34m.[0m[0mcbook[0m [0;32mimport[0m [0mmplDeprecation[0m  [0;31m# deprecated[0m[0;34m[0m[0;34m[0m[0m

[0;32m/Library/Frameworks/Python.framework/Versions/3.10/lib/python3.10/site-packages/matplotlib/cbook/__init__.py[0m in [0;36m<module>[0;34m[0m
[1;32m     29[0m [0;34m[0m[0m
[1;32m     30[0m [0;32mimport[0m [0mmatplotlib[0m[0;34m[0m[0;34m[0m[0m
[0;32m---> 31[0;31m [0;32mfrom[0m [0mmatplotlib[0m [0;32mimport[0m [0m_api[0m[0;34m,[0m [0m_c_internal_utils[0m[0;34m[0m[0;34m[0m[0m
[0m[1;32m     32[0m from matplotlib._api.deprecation import (
[1;32m     33[0m     MatplotlibDeprecationWarning, mplDeprecation)

[0;31mImportError[0m: dlopen(/Library/Frameworks/Python.framework/Versions/3.10/lib/python3.10/site-packages/matplotlib/_c_internal_utils.cpython-310-darwin.so, 0x0002): tried: '/Library/Frameworks/Python.framework/Versions/3.10/lib/python3.10/site-packages/matplotlib/_c_internal_utils.cpython-310-darwin.so' (mach-o file, but is an incompatible architecture (have 'arm64', need 'x86_64')), '/System/Volumes/Preboot/Cryptexes/OS/Library/Frameworks/Python.framework/Versions/3.10/lib/python3.10/site-packages/matplotlib/_c_internal_utils.cpython-310-darwin.so' (no such file), '/Library/Frameworks/Python.framework/Versions/3.10/lib/python3.10/site-packages/matplotlib/_c_internal_utils.cpython-310-darwin.so' (mach-o file, but is an incompatible architecture (have 'arm64', need 'x86_64'))
ImportError: dlopen(/Library/Frameworks/Python.framework/Versions/3.10/lib/python3.10/site-packages/matplotlib/_c_internal_utils.cpython-310-darwin.so, 0x0002): tried: '/Library/Frameworks/Python.framework/Versions/3.10/lib/python3.10/site-packages/matplotlib/_c_internal_utils.cpython-310-darwin.so' (mach-o file, but is an incompatible architecture (have 'arm64', need 'x86_64')), '/System/Volumes/Preboot/Cryptexes/OS/Library/Frameworks/Python.framework/Versions/3.10/lib/python3.10/site-packages/matplotlib/_c_internal_utils.cpython-310-darwin.so' (no such file), '/Library/Frameworks/Python.framework/Versions/3.10/lib/python3.10/site-packages/matplotlib/_c_internal_utils.cpython-310-darwin.so' (mach-o file, but is an incompatible architecture (have 'arm64', need 'x86_64'))

